Workbook

Sheet A
A3: PEMERINTAH DAERAH PROVINSI JAWA BARAT
A4: DINAS PENDIDIKAN
A5: CABANG DINAS PENDIDIKAN WILAYAH VII
A6: SMA NEGERI 19 BANDUNG
A7: Jl. Ir. H. Juanda (Dago Pojok) Telp. (022) 2502465 Bandung – 40135
A8: DAFTAR SISWA KELAS X
A9: TAHUN PELAJARAN 2026/2027
A10: Kelas : X - A | D10: Wali Kelas : Hj. LAKSMI SUPARTININGSIH ,S.Pd.
A12: NO | B12: NIS | C12: NAMA | D12: JK | E12: KETERANGAN
A13: 1 | B13: 262710001 | C13: ADELIO LIVIANO | D13: L
A14: 2 | B14: 262710002 | C14: AIRA PUTRI ANDRIANI | D14: P
A15: 3 | B15: 262710003 | C15: ALVINO | D15: L
A16: 4 | B16: 262710004 | C16: ANJANI LESTARI | D16: P
A17: 5 | B17: 262710005 | C17: ANTHONY CHRISTOPHER ABRAHAM | D17: L
A18: 6 | B18: 262710006 | C18: AUREL ALVIRA RHONISHA | D18: P
A19: 7 | B19: 262710007 | C19: BINTANG RIZKI JUNIOR | D19: L
A20: 8 | B20: 262710008 | C20: CITRA KHARISMA | D20: P
A21: 9 | B21: 262710009 | C21: CLARA AURA SAFITRI | D21: P
A22: 10 | B22: 262710010 | C22: DESHIFA INTAN GUSLIANTI | D22: P
A23: 11 | B23: 262710011 | C23: DZAIKRA DANISH ALANO | D23: L
A24: 12 | B24: 262710012 | C24: FADHILAH NURIZQI | D24: L
... A56: 44 | B56: 262710044 | C56: YANUAR ALIFIO ALFATH | D56: L
C58: L | D58: 23
C59: P | D59: 21

Sheet B
A2: PEMERINTAH DAERAH PROVINSI JAWA BARAT
A3: DINAS PENDIDIKAN
A4: CABANG DINAS PENDIDIKAN WILAYAH VII
A5: SMA NEGERI 19 BANDUNG
A6: Jl. Ir. H. Juanda (Dago Pojok) Telp. (022) 2502465 Bandung – 40135
A7: DAFTAR SISWA KELAS X
A8: TAHUN PELAJARAN 2026/2027
A9: Kelas : X - B | C9: Wali Kelas : MULYANA KURNIAWAN , S.Th.I.
A11: NO | B11: NIS | C11: NAMA | D11: JK | E11: KETERANGAN
A12: 1 | B12: 262710045 | C12: ADRIAN SAEFUL PUTRA PERMANA | D12: L
A13: 2 | B13: 262710046 | C13: ALBIAN NAZARA PUTRA | D13: L
A14: 3 | B14: 262710047 | C14: ALYA KHANA SYIBILA | D14: P
A15: 4 | B15: 262710048 | C15: ARDANI SATYA PRATAMA | D15: L
A16: 5 | B16: 262710049 | C16: ARIF HERNAWAN | D16: L
A17: 6 | B17: 262710050 | C17: AVARIELLA JULLYFHEA RAMADAN | D17: P
A18: 7 | B18: 262710051 | C18: CITRA MEILANI | D18: P
A19: 8 | B19: 262710052 | C19: DAFA AHMAD DZAKY | D19: L
A20: 9 | B20: 262710053 | C20: DASTIN APRILI ADREAN | D20: L
A21: 10 | B21: 262710054 | C21: DEVAN RAYA GUSTAMA | D21: L
A22: 11 | B22: 262710055 | C22: FAHMI AHMAD ANSORY | D22: L
A23: 12 | B23: 262710056 | C23: FELICIA PUTRI | D23: P
... A55: 44 | B55: 262710088 | C55: YUZRISAR AVRILLIA DWI PUTRI | D55: P
C57: L | D57: 23
C58: P | D58: 21

Sheet C
A1: PEMERINTAH DAERAH PROVINSI JAWA BARAT
A2: DINAS PENDIDIKAN
A3: CABANG DINAS PENDIDIKAN WILAYAH VII
A4: SMA NEGERI 19 BANDUNG
A5: Jl. Ir. H. Juanda (Dago Pojok) Telp. (022) 2502465 Bandung – 40135
A6: DAFTAR SISWA KELAS X
A7: TAHUN PELAJARAN 2026/2027
A8: Kelas : X - C | D8: Wali Kelas : ELI HAYATI , S.Pd.
A10: NO | B10: NIS | C10: NAMA | D10: JK | E10: KETERANGAN
A11: 1 | B11: 262710089 | C11: ADZIDZAH ADZIZATUN ZANAH
A12: 2 | B12: 262710090 | C12: ALEA QUEENSHA PUTRI PERMADI
A13: 3 | B13: 262710091 | C13: AMABEL DAMARA ELYSIA
A14: 4 | B14: 262710092 | C14: ARDINI AGISTYA RAMADHANI
A15: 5 | B15: 262710093 | C15: AYEESHA KHALIELA ZANDINE
A16: 6 | B16: 262710094 | C16: AZAHRA NURAENI ALAWIYAH
A17: 7 | B17: 262710095 | C17: BAGAS ARIEF ADZZIKRA
A18: 8 | B18: 262710096 | C18: CANTIKA DEWI NURHERLIANTY
A19: 9 | B19: 262710097 | C19: DARA MUTIA ARDIANTI
A20: 10 | B20: 262710098 | C20: DEVI REGINA PUTRI
A21: 11 | B21: 262710099 | C21: DIMAS CAHYA PRATAMA
A22: 12 | B22: 262710100 | C22: FAKHRI FAUZAN RAMDAN
... A54: 44 | B54: 262710132 | C54: ZAHIRA SYAQINA ARIWIBAWA MULYA
C56: L | D56: 16
C57: P | D57: 28

Sheet D
A2: PEMERINTAH DAERAH PROVINSI JAWA BARAT
A3: DINAS PENDIDIKAN
A4: CABANG DINAS PENDIDIKAN WILAYAH VII
A5: SMA NEGERI 19 BANDUNG
A6: Jl. Ir. H. Juanda (Dago Pojok) Telp. (022) 2502465 Bandung – 40135
A7: DAFTAR SISWA KELAS X
A8: TAHUN PELAJARAN 2026/2027
A9: Kelas : X - D | D9: Wali Kelas : EVI HENDRAYANI , S.Pd.
A11: NO | B11: NIS | C11: NAMA | D11: JK | E11: KETERANGAN
A12: 1 | B12: 262710133 | C12: ABDULLAH BAIHAQI NAZLAH | D12: L
A13: 2 | B13: 262710134 | C13: ADZIZD HAQIM | D13: L
A14: 3 | B14: 262710135 | C14: AKEELA FAIHA BAKHITA | D14: P
A15: 4 | B15: 262710136 | C15: ALIFA DWINOVA SHALIHA | D15: P
A16: 5 | B16: 262710137 | C16: ANNISA PUTRI FAHIRA | D16: P
A17: 6 | B17: 262710138 | C17: ARIQ MU`AFA FAUZAN | D17: L
A18: 7 | B18: 262710139 | C18: AYUMI KIREINA AFLAH | D18: P
A19: 8 | B19: 262710140 | C19: BALQIES NAJLA PUTRI RAHMANI | D19: P
A20: 9 | B20: 262710141 | C20: CAESAR PUTRA PRATAMA | D20: L
A21: 10 | B21: 262710142 | C21: DAFA ZALFANY RASYDAN | D21: L
A22: 11 | B22: 262710143 | C22: DENA TAUFIK NUGRAHA | D22: L
A23: 12 | B23: 262710144 | C23: DHAFIN FAUZAN DAFANDRYAN | D23: L
... A55: 44 | B55: 262710176 | C55: ZHIFARA NURAULIA RAMADHANI | D55: P
C57: L | D57: 21
C58: P | D58: 23

Sheet E
A2: PEMERINTAH DAERAH PROVINSI JAWA BARAT
A3: DINAS PENDIDIKAN
A4: CABANG DINAS PENDIDIKAN WILAYAH VII
A5: SMA NEGERI 19 BANDUNG
A6: Jl. Ir. H. Juanda (Dago Pojok) Telp. (022) 2502465 Bandung – 40135
A7: DAFTAR SISWA KELAS X
A8: TAHUN PELAJARAN 2026/2027
A9: Kelas : X - E | C9: Wali Kelas : Hj. NENI SURYANI, S.Pd.
A11: NO | B11: NIS | C11: NAMA | D11: JK | E11: KETERANGAN
A12: 1 | B12: 262710177 | C12: AISYAH MULYADI | D12: P
A13: 2 | B13: 262710178 | C13: ALEISYA NAFADILLA RISMAWAN | D13: P
A14: 3 | B14: 262710179 | C14: ALIKA AIRA LATHIF | D14: P
A15: 4 | B15: 262710180 | C15: ARKA DWI PUTRA | D15: L
A16: 5 | B16: 262710181 | C16: ARMAN MUCTHAR | D16: L
A17: 6 | B17: 262710182 | C17: BEBI HAFZAH AURELIA | D17: P
A18: 7 | B18: 262710183 | C18: DAFFA FAIZ FADHALAH | D18: L
A19: 8 | B19: 262710184 | C19: DAMAR WAHYUDI | D19: L
A20: 9 | B20: 262710185 | C20: DIMAS SAPUTRA | D20: L
A21: 10 | B21: 262710186 | C21: DINDA PRIADI | D21: P
A22: 11 | B22: 262710187 | C22: DIRA MUSTIKA WARDANY | D22: P
A23: 12 | B23: 262710188 | C23: FARAH MEIDA PUTRI | D23: P
... A55: 44 | B55: 262710220 | C55: ZAYDA BINTANG QUINZA | D55: P
C57: L | D57: 18
C58: P | D58: 26

Sheet F
A2: PEMERINTAH DAERAH PROVINSI JAWA BARAT
A3: DINAS PENDIDIKAN
A4: CABANG DINAS PENDIDIKAN WILAYAH VII
A5: SMA NEGERI 19 BANDUNG
A6: Jl. Ir. H. Juanda (Dago Pojok) Telp. (022) 2502465 Bandung – 40135
A7: DAFTAR SISWA KELAS X
A8: TAHUN PELAJARAN 2026/2027
A9: Kelas : X - F | D9: Wali Kelas : ANGGIA DEVI CHANDRA A. , S.Pd.,M.Si.
A11: NO | B11: NIS | C11: NAMA | D11: JK | E11: KETERANGAN
A12: 1 | B12: 262710221 | C12: ADI NURROHMAN
A13: 2 | B13: 262710222 | C13: AKBAR RIZKIA RIDWAN
A14: 3 | B14: 262710223 | C14: AKHMAD VIERMANSYAH
A15: 4 | B15: 262710224 | C15: ALIYA FITARANI SUKMA DEWI
A16: 5 | B16: 262710225 | C16: APHRADITHA ZAHRA ARRAHMI
A17: 6 | B17: 262710226 | C17: ARVA PRATAMA NUZULUL MAULUDIN
B18: 262710227 | C18: ASHIL HAMIDAH
A19: 7 | B19: 262710228 | C19: ASYIFA KHOIRUNISA
A20: 8 | B20: 262710229 | C20: BRAHMA PUTRA BAGAZ
A21: 9 | B21: 262710230 | C21: DAFFA RAMDHANI CAHYANA
A22: 10 | B22: 262710231 | C22: DEANDRA NARAYANA ISMAIL
A23: 11 | B23: 262710232 | C23: DELLA PUSPITA
A24: 12 | B24: 262710233 | C24: DJULFA SYIFA ROYANI
A25: 13 | B25: 262710234 | C25: EILANA HASYA AQILA
A26: 15 | B26: 262710235 | C26: FARANDZOLLA DAVRIANANDA ALVINO LUWIA
A27: 16 | B27: 262710236 | C27: FITRA RAMADAN SULAEMAN
A28: 17 | B28: 262710237 | C28: HAKIKI KUSTIAWAN NURHAKIM
A29: 18 | B29: 262710238 | C29: IKHSAN REZKY RAMDHANI
A30: 19 | B30: 262710239 | C30: JABAR HERDANA PRAYATA
... A55: 44 | B55: 262710264 | C55: VERA DESTIANI
C57: L | D57: 22
C58: P | D58: 22

Sheet G
A5: PEMERINTAH DAERAH PROVINSI JAWA BARAT
A6: DINAS PENDIDIKAN
A7: CABANG DINAS PENDIDIKAN WILAYAH VII
A8: SMA NEGERI 19 BANDUNG
A9: Jl. Ir. H. Juanda (Dago Pojok) Telp. (022) 2502465 Bandung – 40135
A10: DAFTAR SISWA KELAS X
A11: TAHUN PELAJARAN 2026/2027
A12: Kelas : X - G | D12: Wali Kelas : TRISNO , S.E.
A14: NO | B14: NIS | C14: NAMA | D14: JK | E14: KETERANGAN
A15: 1 | B15: 262710265 | C15: ADINDA NURUL FATIMAH
A16: 2 | B16: 262710266 | C16: ALDA RAINA SETIAWAN
A17: 3 | B17: 262710265 | C17: ALYA ZAHRA FATIHA
A18: 4 | B18: 262710266 | C18: ARIZKA AMALYA SYAHIDA
A19: 5 | B19: 262710267 | C19: ARYA JANUAR PRASETYA
A20: 6 | B20: 262710268 | C20: ASKANTARA RAJA AL- ABIYYU
A21: 7 | B21: 262710269 | C21: ASYIFA NUR FADILAH
A22: 8 | B22: 262710270 | C22: CALISTA CITRA CEMPAKA
A23: 9 | B23: 252610242 | C23: DAMIAN NOVRE VALIANT
A24: 10 | B24: 262710271 | C24: DARRA ANUGRAH
A25: 11 | B25: 262710272 | C25: DENDI NABIL FRIZZI
A26: 12 | B26: 262710274 | C26: DZAKI DANISWARA
... A58: 44 | B58: 262710306 | C58: VARIQ XAVIER VALZIKRI
C60: L | D60: 23
C61: P | D61: 21

Sheet H
A5: PEMERINTAH DAERAH PROVINSI JAWA BARAT
A6: DINAS PENDIDIKAN
A7: CABANG DINAS PENDIDIKAN WILAYAH VII
A8: SMA NEGERI 19 BANDUNG
A9: Jl. Ir. H. Juanda (Dago Pojok) Telp. (022) 2502465 Bandung – 40135
A10: DAFTAR SISWA KELAS X
A11: TAHUN PELAJARAN 2026/2027
A12: Kelas : X - H | D12: Wali Kelas : IRMA PRIMAWATI , S.Pd.
A14: NO | B14: NIS | C14: NAMA | D14: JK | E14: KETERANGAN
A15: 1 | B15: 262710307 | C15: AGUNG WAHYU NUGRAHA | D15: L
A16: 2 | B16: 262710308 | C16: ALI MUHAMMAD HASAN | D16: L
A17: 3 | B17: 262710309 | C17: ANIRA PUTRI HIDAYAT | D17: P
A18: 4 | B18: 262710310 | C18: ARRIZA SNADA TRI PUTRA | D18: L
A19: 5 | B19: 262710311 | C19: ASHABBEL PINERA TARMA PUTRINA WANDI | D19: P
A20: 6 | B20: 262710312 | C20: AZALIA QUINCY ARIESTY | D20: P
A21: 7 | B21: 262710313 | C21: AZKIYA DWIPUTRI NAYLA | D21: P
A22: 8 | B22: 262710314 | C22: CARISSA PUTRI ALNABIRA | D22: P
A23: 9 | B23: 262710315 | C23: DAVIN AGRA ARDIANA PUTRA | D23: L
A24: 10 | B24: 262710316 | C24: DISYA RAHIL ANJANI | D24: P
A25: 11 | B25: 262710317 | C25: EMILA ZAHIRA | D25: P
A26: 12 | B26: 262710318 | C26: FARID FATHUDDIN ALI | D26: L
... A58: 44 | B58: 262710349 | C58: YUDA SAPUTRA | D58: L
C60: L | D60: 19
C61: P | D61: 25

Sheet I
A6: PEMERINTAH DAERAH PROVINSI JAWA BARAT
A7: DINAS PENDIDIKAN
A8: CABANG DINAS PENDIDIKAN WILAYAH VII
A9: SMA NEGERI 19 BANDUNG
A10: Jl. Ir. H. Juanda (Dago Pojok) Telp. (022) 2502465 Bandung – 40135
A11: DAFTAR SISWA KELAS X
A12: TAHUN PELAJARAN 2026/2027
A13: Kelas : X - I | D13: Wali Kelas : ERI SAPTARI YUNIRMAN , S.Pd.
A15: NO | B15: NIS | C15: NAMA | D15: JK | E15: KETERANGAN
A16: 1 | B16: 262710350 | C16: AGUS RAMDAN
A17: 2 | B17: 262710351 | C17: ALLYSHCA PUTRI HAOIKHA
A18: 3 | B18: 262710352 | C18: ARDELIA TIRANA ARIESTA
A19: 4 | B19: 262710353 | C19: ARVIKA OKTAVIANI
A20: 5 | B20: 262710354 | C20: ASHADIYA NAZLA ARKANA
A21: 6 | B21: 262710355 | C21: AYU MUSYAROPAH
A22: 7 | B22: 262710356 | C22: AZIS FADHIANSYAH
A23: 8 | B23: 262710357 | C23: AZZAHRA NURSALWA ZAINA WINARDI
A24: 9 | B24: 262710358 | C24: CHAIRUL ZAIWA RADITIA
A25: 10 | B25: 262710359 | C25: DEANDRA ADITYA PRATAMA
A26: 11 | B26: 262710360 | C26: EKA NOVITA PUTRI AGUSTIN
A27: 12 | B27: 262710361 | C27: FAIZ RAIHAN HUSEIN
... A58: 43 | B58: 262710392 | C58: ZAHWA NURUL ZULFAH
C60: L | D60: 16
C61: P | D61: 27

Sheet J
A5: PEMERINTAH DAERAH PROVINSI JAWA BARAT
A6: DINAS PENDIDIKAN
A7: CABANG DINAS PENDIDIKAN WILAYAH VII
A8: SMA NEGERI 19 BANDUNG
A9: Jl. Ir. H. Juanda (Dago Pojok) Telp. (022) 2502465 Bandung – 40135
A10: DAFTAR SISWA KELAS X
A11: TAHUN PELAJARAN 2026/2027
A12: Kelas : X - J | D12: Wali Kelas : ECIN KURAESIN , S.Pd.
A14: NO | B14: NIS | C14: NAMA | D14: JK | E14: KETERANGAN
A15: 1 | B15: 262710393 | C15: ADISTI NILAM GITARI | D15: P
A16: 2 | B16: 262710394 | C16: ADITYA NOVA SAPUTRA | D16: L
A17: 3 | B17: 262710395 | C17: AHSYA PUTRI SYAROFFA | D17: P
A18: 4 | B18: 262710396 | C18: AJENG YULIA RAMADHANI | D18: L
A19: 5 | B19: 262710397 | C19: AKBAR AUNILLAH SOFYAN | D19: P
A20: 6 | B20: 262710398 | C20: ALTHAN MAHVIN DINARA | D20: L
A21: 7 | B21: 262710399 | C21: ASHVIN NU`MAN AWALUDIN | D21: L
A22: 8 | B22: 262710400 | C22: BIANCA AURORA SHAHRANI ILHAM | D22: P
A23: 9 | B23: 262710401 | C23: CHALIS KIRANA WINALDA | D23: P
A24: 10 | B24: 262710402 | C24: CHANTIKA KIRANA PUTRI | D24: P
A25: 11 | B25: 262710403 | C25: DEFA CANDRA | D25: L
A26: 12 | B26: 262710404 | C26: ELIZA APRILIANI | D26: P
... A58: 44 | B58: 262710436 | C58: ZUANS ZUMAR SHAFALA | D58: L
C59: L | D59: 19
C60: P | D60: 25

Sheet K
A5: PEMERINTAH DAERAH PROVINSI JAWA BARAT
A6: DINAS PENDIDIKAN
A7: CABANG DINAS PENDIDIKAN WILAYAH VII
A8: SMA NEGERI 19 BANDUNG
A9: Jl. Ir. H. Juanda (Dago Pojok) Telp. (022) 2502465 Bandung – 40135
A10: DAFTAR SISWA KELAS X
A11: TAHUN PELAJARAN 2026/2027
A12: Kelas : X - K | D12: Wali Kelas : INTAN MUTIARA , S.Pd.
A14: NO | B14: NIS | C14: NAMA | D14: JK | E14: KETERANGAN
A15: 1 | B15: 262710437 | C15: AGHISTA PRATAMA PUTRA RAMADHAN | D15: L
A16: 2 | B16: 252610188 | C16: AGUSTIN NURAENI | D16: P
A17: 3 | B17: 262710438 | C17: AL FEBRIANSYAH SEPTIAN | D17: L
A18: 4 | B18: 262710439 | C18: ALVIAN DWI HARI BHAYANGKARA | D18: L
A19: 5 | B19: 262710440 | C19: ANGEL APRILIA | D19: P
A20: 6 | B20: 262710441 | C20: AULIA AZAHRA ANASYA | D20: P
A21: 7 | B21: 262710442 | C21: BILAL TSAQIF PRAYOGA | D21: L
A22: 8 | B22: 262710443 | C22: CHERRY ADZKIYA AL KHANZA | D22: P
A23: 9 | B23: 262710444 | C23: CINDY RIZKYA OKTAVIANTRI | D23: P
A24: 10 | B24: 262710445 | C24: DAVINA HARMALIA PUTRI | D24: P
A25: 11 | B25: 262710446 | C25: DENI ISKANDAR | D25: L
A26: 12 | B26: 262710447 | C26: ENDRA ADHIBRATA | D26: L
... A58: 44 | B58: 262710479 | C58: ZAHIRA NURASYFA | D58: P
C60: L | D60: 18
C61: P | D61: 26

Sheet PRESENSI FOTO 2025
A1: PEMERINTAH DAERAH PROVINSI JAWA BARAT
A2: DINAS PENDIDIKAN
A3: CABANG DINAS PENDIDIKAN WILAYAH VII
A4: SMA NEGERI 19 BANDUNG
A5: Jl. Ir. H. Juanda (Dago Pojok) Telp. (022) 2502465 Bandung – 40135
A6: DAFTAR PENERIMA BUKU TATIB
A7: TAHUN PELAJARAN 2025/2026
A8: Kelas : X - A | D8: Wali Kelas : VELIANA NURSYAMSIAH.,M.Pd
A10: NO | B10: NIS | C10: NAMA | D10: L/P | E10: TANDA TANGAN
A12: 1 | B12: =A!B13 -> 262710001 | C12: =A!C13 -> ADELIO LIVIANO | D12: =A!D13 -> L
A13: 2 | B13: =A!B14 -> 262710002 | C13: =A!C14 -> AIRA PUTRI ANDRIANI | D13: =A!D14 -> P
A14: 3 | B14: =A!B15 -> 262710003 | C14: =A!C15 -> ALVINO | D14: =A!D15 -> L
A15: 4 | B15: =A!B16 -> 262710004 | C15: =A!C16 -> ANJANI LESTARI | D15: =A!D16 -> P
A16: 5 | B16: =A!B17 -> 262710005 | C16: =A!C17 -> ANTHONY CHRISTOPHER ABRAHAM | D16: =A!D17 -> L
A17: 6 | B17: =A!B18 -> 262710006 | C17: =A!C18 -> AUREL ALVIRA RHONISHA | D17: =A!D18 -> P
A18: 7 | B18: =A!B19 -> 262710007 | C18: =A!C19 -> BINTANG RIZKI JUNIOR | D18: =A!D19 -> L
A19: 8 | B19: =A!B20 -> 262710008 | C19: =A!C20 -> CITRA KHARISMA | D19: =A!D20 -> P
A20: 9 | B20: =A!B21 -> 262710009 | C20: =A!C21 -> CLARA AURA SAFITRI | D20: =A!D21 -> P
A21: 10 | B21: =A!B22 -> 262710010 | C21: =A!C22 -> DESHIFA INTAN GUSLIANTI | D21: =A!D22 -> P
A22: 11 | B22: =A!B23 -> 262710011 | C22: =A!C23 -> DZAIKRA DANISH ALANO | D22: =A!D23 -> L
A23: 12 | B23: =A!B24 -> 262710012 | C23: =A!C24 -> FADHILAH NURIZQI | D23: =A!D24 -> L
... A55: 44 | B55: =A!B56 -> 262710044 | C55: =A!C56 -> YANUAR ALIFIO ALFATH | D55: =A!D56 -> L
A56: 45 | B56: =A!#REF! -> #REF! | C56: =A!#REF! -> #REF! | D56: =A!#REF! -> #REF!
A57: 46 | B57: =A!#REF! -> #REF! | C57: =A!#REF! -> #REF! | D57: =A!#REF! -> #REF!
A58: 47 | B58: =A!#REF! -> #REF! | C58: =A!#REF! -> #REF! | D58: =A!#REF! -> #REF!
B59: L | C59: 23
B60: P | C60: 24
A63: PEMERINTAH DAERAH PROVINSI JAWA BARAT
A64: DINAS PENDIDIKAN
A65: CABANG DINAS PENDIDIKAN WILAYAH VII
A66: SMA NEGERI 19 BANDUNG
A67: Jl. Ir. H. Juanda (Dago Pojok) Telp. (022) 2502465 Bandung – 40135
A68: DAFTAR PENERIMA BUKU TATIB
A69: TAHUN PELAJARAN 2025/2026
A70: Kelas : X - B | C70: Wali Kelas : ROBIYATUL ADAWIYAH, S.Pd.I
A72: NO | B72: NIS | C72: NAMA | D72: L/P | E72: TANDA TANGAN
A74: 1 | B74: 252610048 | C74: AGUS MARIONO | D74: L
A75: 2 | B75: 252610049 | C75: ALEXA DWIVALERA | D75: P
A76: 3 | B76: 252610050 | C76: ALISA NUR FEBIONA | D76: P
A77: 4 | B77: 252610051 | C77: ALLIANA RAISHA HADI | D77: P
...
